Workbook
Name Kategorien: '⚙️ Einstellungen'!$D$6:$D$13

Sheet 📊 Übersicht
A2: LeSousChef · FOOD COST TRACKER · v4 DE
A3: ="Währung: "&'⚙️ Einstellungen'!$B$10&" | Maßsystem: "&'⚙️ Einstellungen'!$B$11
A6: =IF(OR('⚙️ Einstellungen'!$B$7<1,'⚙️ Einstellungen'!$B$7>9),"⚠ FEHLER: Aktive Woche außerhalb des Bereichs (1-9). In Einstellungen B7 korrigieren","WOCHENÜBERSICHT — WOCHE "&'⚙️ Einstellungen'!$B$7)
A7: ="UMSATZ ("&'⚙️ Einstellungen'!$B$10&")" | C7: ="GESAMTKOSTEN ("&'⚙️ Einstellungen'!$B$10&")" | E7: ="SCHWUND ("&'⚙️ Einstellungen'!$B$10&")" | G7: FOOD-COST % | I7: ZIEL FC%
A8: =IFERROR(INDEX('📈 Wochen'!$B$7:$J$7,1,'⚙️ Einstellungen'!$B$7),0) | C8: =IFERROR(INDEX('📈 Wochen'!$B$40:$J$40,1,'⚙️ Einstellungen'!$B$7),0) | E8: =IFERROR(INDEX('📈 Wochen'!$B$29:$J$29,1,'⚙️ Einstellungen'!$B$7),0) | G8: =IFERROR(INDEX('📈 Wochen'!$B$43:$J$43,1,'⚙️ Einstellungen'!$B$7),0) | I8: ='⚙️ Einstellungen'!$B$13
A10: OPERATIVER STATUS
A11: UMSATZ-ALARM | E11: FC-ALARM | I11: TREND 3 WOCHEN
A12: =IFERROR(IF(INDEX('📈 Wochen'!$B$7:$J$7,1,'⚙️ Einstellungen'!$B$7)<'⚙️ Einstellungen'!$B$28,"⚠ NIEDRIGER UMSATZ","✓ OK"),"—") | E12: =IFERROR(IF(INDEX('📈 Wochen'!$B$43:$J$43,1,'⚙️ Einstellungen'!$B$7)>'⚙️ Einstellungen'!$B$13+'⚙️ Einstellungen'!$B$29,"🚨 FC ZU HOCH",IF(INDEX('📈 Wochen'!$B$43:$J$43,1,'⚙️ Einstellungen'!$B$7)>'⚙️ Einstellungen'!$B$13,"⚠ Über Ziel","✓ Im Rahmen")),"—") | I12: =IFERROR(IF('⚙️ Einstellungen'!$B$7<3,"—",IF(COUNTIFS(OFFSET('📈 Wochen'!$A$43,0,'⚙️ Einstellungen'!$B$7-2,1,3),">"&'⚙️ Einstellungen'!$B$13)>=3,"🚨 3 Wo. über Ziel","✓ OK")),"—")
A14: ="AUFSCHLÜSSELUNG NACH KATEGORIE — WOCHE "&'⚙️ Einstellungen'!$B$7
A15: Kategorie | B15: ="Einkäufe ("&'⚙️ Einstellungen'!$B$10&")" | C15: ="Schwund ("&'⚙️ Einstellungen'!$B$10&")" | D15: ="Gesamtkosten ("&'⚙️ Einstellungen'!$B$10&")" | E15: ="Ziel ("&'⚙️ Einstellungen'!$B$10&")" | F15: Abweichung | G15: Trend | H15: Status
A16: Fleisch & Geflügel | B16: =IFERROR(INDEX('📈 Wochen'!$B$19:$J$19,1,'⚙️ Einstellungen'!$B$7),0) | C16: =IFERROR(INDEX('📈 Wochen'!$B$30:$J$30,1,'⚙️ Einstellungen'!$B$7),0) | D16: =B16+C16 | E16: =IFERROR(INDEX('📈 Wochen'!$B$8:$J$8,1,'⚙️ Einstellungen'!$B$7)*'⚙️ Einstellungen'!$B$16,0) | F16: =IFERROR(D16-E16,0) | G16: =IF('⚙️ Einstellungen'!$B$7<=1,"—",IF(INDEX('📈 Wochen'!$B$19:$J$19,1,'⚙️ Einstellungen'!$B$7)+INDEX('📈 Wochen'!$B$30:$J$30,1,'⚙️ Einstellungen'!$B$7)>INDEX('📈 Wochen'!$B$19:$J$19,1,'⚙️ Einstellungen'!$B$7-1)+INDEX('📈 Wochen'!$B$30:$J$30,1,'⚙️ Einstellungen'!$B$7-1),"↑ steigt",IF(INDEX('📈 Wochen'!$B$19:$J$19,1,'⚙️ Einstellungen'!$B$7)+INDEX('📈 Wochen'!$B$30:$J$30,1,'⚙️ Einstellungen'!$B$7)<INDEX('📈 Wochen'!$B$19:$J$19,1,'⚙️ Einstellungen'!$B$7-1)+INDEX('📈 Wochen'!$B$30:$J$30,1,'⚙️ Einstellungen'!$B$7-1),"↓ fällt","= gleich"))) | H16: =IF(D16=0,"—",IF(D16<=E16,"✓ OK","⚠ Prüfen"))
A17: Fisch & Meeresfrüchte | B17: =IFERROR(INDEX('📈 Wochen'!$B$20:$J$20,1,'⚙️ Einstellungen'!$B$7),0) | C17: =IFERROR(INDEX('📈 Wochen'!$B$31:$J$31,1,'⚙️ Einstellungen'!$B$7),0) | D17: =B17+C17 | E17: =IFERROR(INDEX('📈 Wochen'!$B$9:$J$9,1,'⚙️ Einstellungen'!$B$7)*'⚙️ Einstellungen'!$B$17,0) | F17: =IFERROR(D17-E17,0) | G17: =IF('⚙️ Einstellungen'!$B$7<=1,"—",IF(INDEX('📈 Wochen'!$B$20:$J$20,1,'⚙️ Einstellungen'!$B$7)+INDEX('📈 Wochen'!$B$31:$J$31,1,'⚙️ Einstellungen'!$B$7)>INDEX('📈 Wochen'!$B$20:$J$20,1,'⚙️ Einstellungen'!$B$7-1)+INDEX('📈 Wochen'!$B$31:$J$31,1,'⚙️ Einstellungen'!$B$7-1),"↑ steigt",IF(INDEX('📈 Wochen'!$B$20:$J$20,1,'⚙️ Einstellungen'!$B$7)+INDEX('📈 Wochen'!$B$31:$J$31,1,'⚙️ Einstellungen'!$B$7)<INDEX('📈 Wochen'!$B$20:$J$20,1,'⚙️ Einstellungen'!$B$7-1)+INDEX('📈 Wochen'!$B$31:$J$31,1,'⚙️ Einstellungen'!$B$7-1),"↓ fällt","= gleich"))) | H17: =IF(D17=0,"—",IF(D17<=E17,"✓ OK","⚠ Prüfen"))
A18: Obst & Gemüse | B18: =IFERROR(INDEX('📈 Wochen'!$B$21:$J$21,1,'⚙️ Einstellungen'!$B$7),0) | C18: =IFERROR(INDEX('📈 Wochen'!$B$32:$J$32,1,'⚙️ Einstellungen'!$B$7),0) | D18: =B18+C18 | E18: =IFERROR(INDEX('📈 Wochen'!$B$10:$J$10,1,'⚙️ Einstellungen'!$B$7)*'⚙️ Einstellungen'!$B$18,0) | F18: =IFERROR(D18-E18,0) | G18: =IF('⚙️ Einstellungen'!$B$7<=1,"—",IF(INDEX('📈 Wochen'!$B$21:$J$21,1,'⚙️ Einstellungen'!$B$7)+INDEX('📈 Wochen'!$B$32:$J$32,1,'⚙️ Einstellungen'!$B$7)>INDEX('📈 Wochen'!$B$21:$J$21,1,'⚙️ Einstellungen'!$B$7-1)+INDEX('📈 Wochen'!$B$32:$J$32,1,'⚙️ Einstellungen'!$B$7-1),"↑ steigt",IF(INDEX('📈 Wochen'!$B$21:$J$21,1,'⚙️ Einstellungen'!$B$7)+INDEX('📈 Wochen'!$B$32:$J$32,1,'⚙️ Einstellungen'!$B$7)<INDEX('📈 Wochen'!$B$21:$J$21,1,'⚙️ Einstellungen'!$B$7-1)+INDEX('📈 Wochen'!$B$32:$J$32,1,'⚙️ Einstellungen'!$B$7-1),"↓ fällt","= gleich"))) | H18: =IF(D18=0,"—",IF(D18<=E18,"✓ OK","⚠ Prüfen"))
A19: Milchprodukte & Eier | B19: =IFERROR(INDEX('📈 Wochen'!$B$22:$J$22,1,'⚙️ Einstellungen'!$B$7),0) | C19: =IFERROR(INDEX('📈 Wochen'!$B$33:$J$33,1,'⚙️ Einstellungen'!$B$7),0) | D19: =B19+C19 | E19: =IFERROR(INDEX('📈 Wochen'!$B$11:$J$11,1,'⚙️ Einstellungen'!$B$7)*'⚙️ Einstellungen'!$B$19,0) | F19: =IFERROR(D19-E19,0) | G19: =IF('⚙️ Einstellungen'!$B$7<=1,"—",IF(INDEX('📈 Wochen'!$B$22:$J$22,1,'⚙️ Einstellungen'!$B$7)+INDEX('📈 Wochen'!$B$33:$J$33,1,'⚙️ Einstellungen'!$B$7)>INDEX('📈 Wochen'!$B$22:$J$22,1,'⚙️ Einstellungen'!$B$7-1)+INDEX('📈 Wochen'!$B$33:$J$33,1,'⚙️ Einstellungen'!$B$7-1),"↑ steigt",IF(INDEX('📈 Wochen'!$B$22:$J$22,1,'⚙️ Einstellungen'!$B$7)+INDEX('📈 Wochen'!$B$33:$J$33,1,'⚙️ Einstellungen'!$B$7)<INDEX('📈 Wochen'!$B$22:$J$22,1,'⚙️ Einstellungen'!$B$7-1)+INDEX('📈 Wochen'!$B$33:$J$33,1,'⚙️ Einstellungen'!$B$7-1),"↓ fällt","= gleich"))) | H19: =IF(D19=0,"—",IF(D19<=E19,"✓ OK","⚠ Prüfen"))
A20: Backwaren & Konditorei | B20: =IFERROR(INDEX('📈 Wochen'!$B$23:$J$23,1,'⚙️ Einstellungen'!$B$7),0) | C20: =IFERROR(INDEX('📈 Wochen'!$B$34:$J$34,1,'⚙️ Einstellungen'!$B$7),0) | D20: =B20+C20 | E20: =IFERROR(INDEX('📈 Wochen'!$B$12:$J$12,1,'⚙️ Einstellungen'!$B$7)*'⚙️ Einstellungen'!$B$20,0) | F20: =IFERROR(D20-E20,0) | G20: =IF('⚙️ Einstellungen'!$B$7<=1,"—",IF(INDEX('📈 Wochen'!$B$23:$J$23,1,'⚙️ Einstellungen'!$B$7)+INDEX('📈 Wochen'!$B$34:$J$34,1,'⚙️ Einstellungen'!$B$7)>INDEX('📈 Wochen'!$B$23:$J$23,1,'⚙️ Einstellungen'!$B$7-1)+INDEX('📈 Wochen'!$B$34:$J$34,1,'⚙️ Einstellungen'!$B$7-1),"↑ steigt",IF(INDEX('📈 Wochen'!$B$23:$J$23,1,'⚙️ Einstellungen'!$B$7)+INDEX('📈 Wochen'!$B$34:$J$34,1,'⚙️ Einstellungen'!$B$7)<INDEX('📈 Wochen'!$B$23:$J$23,1,'⚙️ Einstellungen'!$B$7-1)+INDEX('📈 Wochen'!$B$34:$J$34,1,'⚙️ Einstellungen'!$B$7-1),"↓ fällt","= gleich"))) | H20: =IF(D20=0,"—",IF(D20<=E20,"✓ OK","⚠ Prüfen"))
A21: Alkoholfreie Getränke | B21: =IFERROR(INDEX('📈 Wochen'!$B$24:$J$24,1,'⚙️ Einstellungen'!$B$7),0) | C21: =IFERROR(INDEX('📈 Wochen'!$B$35:$J$35,1,'⚙️ Einstellungen'!$B$7),0) | D21: =B21+C21 | E21: =IFERROR(INDEX('📈 Wochen'!$B$13:$J$13,1,'⚙️ Einstellungen'!$B$7)*'⚙️ Einstellungen'!$B$21,0) | F21: =IFERROR(D21-E21,0) | G21: =IF('⚙️ Einstellungen'!$B$7<=1,"—",IF(INDEX('📈 Wochen'!$B$24:$J$24,1,'⚙️ Einstellungen'!$B$7)+INDEX('📈 Wochen'!$B$35:$J$35,1,'⚙️ Einstellungen'!$B$7)>INDEX('📈 Wochen'!$B$24:$J$24,1,'⚙️ Einstellungen'!$B$7-1)+INDEX('📈 Wochen'!$B$35:$J$35,1,'⚙️ Einstellungen'!$B$7-1),"↑ steigt",IF(INDEX('📈 Wochen'!$B$24:$J$24,1,'⚙️ Einstellungen'!$B$7)+INDEX('📈 Wochen'!$B$35:$J$35,1,'⚙️ Einstellungen'!$B$7)<INDEX('📈 Wochen'!$B$24:$J$24,1,'⚙️ Einstellungen'!$B$7-1)+INDEX('📈 Wochen'!$B$35:$J$35,1,'⚙️ Einstellungen'!$B$7-1),"↓ fällt","= gleich"))) | H21: =IF(D21=0,"—",IF(D21<=E21,"✓ OK","⚠ Prüfen"))
A22: Trocken- & Konservenware | B22: =IFERROR(INDEX('📈 Wochen'!$B$25:$J$25,1,'⚙️ Einstellungen'!$B$7),0) | C22: =IFERROR(INDEX('📈 Wochen'!$B$36:$J$36,1,'⚙️ Einstellungen'!$B$7),0) | D22: =B22+C22 | E22: =IFERROR(INDEX('📈 Wochen'!$B$14:$J$14,1,'⚙️ Einstellungen'!$B$7)*'⚙️ Einstellungen'!$B$22,0) | F22: =IFERROR(D22-E22,0) | G22: =IF('⚙️ Einstellungen'!$B$7<=1,"—",IF(INDEX('📈 Wochen'!$B$25:$J$25,1,'⚙️ Einstellungen'!$B$7)+INDEX('📈 Wochen'!$B$36:$J$36,1,'⚙️ Einstellungen'!$B$7)>INDEX('📈 Wochen'!$B$25:$J$25,1,'⚙️ Einstellungen'!$B$7-1)+INDEX('📈 Wochen'!$B$36:$J$36,1,'⚙️ Einstellungen'!$B$7-1),"↑ steigt",IF(INDEX('📈 Wochen'!$B$25:$J$25,1,'⚙️ Einstellungen'!$B$7)+INDEX('📈 Wochen'!$B$36:$J$36,1,'⚙️ Einstellungen'!$B$7)<INDEX('📈 Wochen'!$B$25:$J$25,1,'⚙️ Einstellungen'!$B$7-1)+INDEX('📈 Wochen'!$B$36:$J$36,1,'⚙️ Einstellungen'!$B$7-1),"↓ fällt","= gleich"))) | H22: =IF(D22=0,"—",IF(D22<=E22,"✓ OK","⚠ Prüfen"))
A23: Sonstiges | B23: =IFERROR(INDEX('📈 Wochen'!$B$26:$J$26,1,'⚙️ Einstellungen'!$B$7),0) | C23: =IFERROR(INDEX('📈 Wochen'!$B$37:$J$37,1,'⚙️ Einstellungen'!$B$7),0) | D23: =B23+C23 | E23: =IFERROR(INDEX('📈 Wochen'!$B$15:$J$15,1,'⚙️ Einstellungen'!$B$7)*'⚙️ Einstellungen'!$B$23,0) | F23: =IFERROR(D23-E23,0) | G23: =IF('⚙️ Einstellungen'!$B$7<=1,"—",IF(INDEX('📈 Wochen'!$B$26:$J$26,1,'⚙️ Einstellungen'!$B$7)+INDEX('📈 Wochen'!$B$37:$J$37,1,'⚙️ Einstellungen'!$B$7)>INDEX('📈 Wochen'!$B$26:$J$26,1,'⚙️ Einstellungen'!$B$7-1)+INDEX('📈 Wochen'!$B$37:$J$37,1,'⚙️ Einstellungen'!$B$7-1),"↑ steigt",IF(INDEX('📈 Wochen'!$B$26:$J$26,1,'⚙️ Einstellungen'!$B$7)+INDEX('📈 Wochen'!$B$37:$J$37,1,'⚙️ Einstellungen'!$B$7)<INDEX('📈 Wochen'!$B$26:$J$26,1,'⚙️ Einstellungen'!$B$7-1)+INDEX('📈 Wochen'!$B$37:$J$37,1,'⚙️ Einstellungen'!$B$7-1),"↓ fällt","= gleich"))) | H23: =IF(D23=0,"—",IF(D23<=E23,"✓ OK","⚠ Prüfen"))
A24: GESAMT | B24: =SUM(B16:B23) | C24: =SUM(C16:C23) | D24: =SUM(D16:D23) | E24: =SUM(E16:E23) | F24: =SUM(F16:F23)
A26: 💡 Schwund wird automatisch aus dem Inventar-Log übernommen. Trend vergleicht mit der Vorwoche.
A28: LeSousChef · lesouschef.com · Dozo Tech · SYSTEMS THAT BREATHE

Sheet ⚙️ Einstellungen
A1: RESTAURANT-EINSTELLUNGEN
A4: RESTAURANT-ANGABEN | D4: HAUPTKATEGORIEN
A5: Restaurantname | B5: Mein Restaurant | D5: Liste für die Datenvalidierung in allen Blättern
A6: Verantwortlich | D6: Fleisch & Geflügel
A7: Aktive Woche (Nr. 1-9) | B7: 1 | D7: Fisch & Meeresfrüchte
A8: Jahr | B8: 2025 | D8: Obst & Gemüse
A9: GLOBALE EINSTELLUNGEN | D9: Milchprodukte & Eier
A10: Währung | B10: EUR | D10: Backwaren & Konditorei
A11: Maßsystem | B11: Metric | D11: Alkoholfreie Getränke
A12: Währung und Maßsystem wählen. Wirkt auf alle Blätter. | D12: Trocken- & Konservenware
A13: GLOBALES Food-Cost-Ziel % | B13: 0.3 | D13: Sonstiges
A14: FOOD-COST-ZIELE
A15: Kategorie | B15: Ziel FC%
A16: Fleisch & Geflügel | B16: 0.35 | D16: NEU IN v4
A17: Fisch & Meeresfrüchte | B17: 0.38 | D17: ✓ Globale Wahl von Währung und Maßsystem
A18: Obst & Gemüse | B18: 0.25 | D18: ✓ Schwund beeinflusst automatisch Food-Cost %
A19: Milchprodukte & Eier | B19: 0.28 | D19: ✓ Trend-Spalte (↑↓=) pro Kategorie
A20: Backwaren & Konditorei | B20: 0.3 | D20: ✓ Alarm bei niedrigem Wochenumsatz
A21: Alkoholfreie Getränke | B21: 0.2 | D21: ✓ Alarm bei 3 Wochen über Ziel
A22: Trocken- & Konservenware | B22: 0.22 | D22: ✓ Stückkosten per SVERWEIS Lieferanten → Inventar
A23: Sonstiges | B23: 0.25 | D23: ✓ Validierung der aktiven Woche (1-9)
D25: NUTZUNGS-ABLAUF:
A26: ALARM-SCHWELLEN | D26: 1. Währung und Einheiten in B10-B11 wählen
A27: Schwellen, die Alarme in der Übersicht auslösen | D27: 2. Preise in "🏪 Lieferanten" eintragen
A28: Mindestumsatz pro Woche | B28: 3000 | D28: 3. Artikel + Bestand in "📦 Inventar" eintragen (Preis auto)
A29: FC-Toleranz vor rotem Alarm | B29: 0.05 | D29: 4. Umsatz und Einkäufe in "📈 Wochen" erfassen
D30: 5. Schwund im "📦 Inventar" protokollieren
D31: 6. Aktive Woche in B7 ändern → Übersicht aktualisiert sich
D33: REFERENZ — TYPISCHE FC%-SPANNEN:
D34: · Casual: 28–35% · Fine Dining: 32–38%
D35: · Fast Casual: 25–30% · Café: 22–28%
A37: LeSousChef · lesouschef.com · Dozo Tech · SYSTEMS THAT BREATHE

Sheet 📈 Wochen
A1: WÖCHENTLICHES FOOD-COST-LOG
A2: ="Währung: "&'⚙️ Einstellungen'!$B$10&" | Maßsystem: "&'⚙️ Einstellungen'!$B$11
A4: Kennzahl | B4: Woche 1 | C4: Woche 2 | D4: Woche 3 | E4: Woche 4 | F4: Woche 5 | G4: Woche 6 | H4: Woche 7 | I4: Woche 8 | J4: Woche 9
A5: Wochenbeginn
A6: UMSATZ
A7: Gesamter Nettoumsatz | B7: =SUM(B8:B15) | C7: =SUM(C8:C15) | D7: =SUM(D8:D15) | E7: =SUM(E8:E15) | F7: =SUM(F8:F15) | G7: =SUM(G8:G15) | H7: =SUM(H8:H15) | I7: =SUM(I8:I15) | J7: =SUM(J8:J15)
A8: Umsatz — Fleisch & Geflügel | B8: 0 | C8: 0 | D8: 0 | E8: 0 | F8: 0 | G8: 0 | H8: 0 | I8: 0 | J8: 0
A9: Umsatz — Fisch & Meeresfrüchte | B9: 0 | C9: 0 | D9: 0 | E9: 0 | F9: 0 | G9: 0 | H9: 0 | I9: 0 | J9: 0
A10: Umsatz — Obst & Gemüse | B10: 0 | C10: 0 | D10: 0 | E10: 0 | F10: 0 | G10: 0 | H10: 0 | I10: 0 | J10: 0
A11: Umsatz — Milchprodukte & Eier | B11: 0 | C11: 0 | D11: 0 | E11: 0 | F11: 0 | G11: 0 | H11: 0 | I11: 0 | J11: 0
A12: Umsatz — Backwaren & Konditorei | B12: 0 | C12: 0 | D12: 0 | E12: 0 | F12: 0 | G12: 0 | H12: 0 | I12: 0 | J12: 0
A13: Umsatz — Alkoholfreie Getränke | B13: 0 | C13: 0 | D13: 0 | E13: 0 | F13: 0 | G13: 0 | H13: 0 | I13: 0 | J13: 0
A14: Umsatz — Trocken- & Konservenware | B14: 0 | C14: 0 | D14: 0 | E14: 0 | F14: 0 | G14: 0 | H14: 0 | I14: 0 | J14: 0
A15: Umsatz — Sonstiges | B15: 0 | C15: 0 | D15: 0 | E15: 0 | F15: 0 | G15: 0 | H15: 0 | I15: 0 | J15: 0
A17: EINKÄUFE (vor Schwund)
A18: Gesamteinkäufe | B18: =SUM(B19:B26) | C18: =SUM(C19:C26) | D18: =SUM(D19:D26) | E18: =SUM(E19:E26) | F18: =SUM(F19:F26) | G18: =SUM(G19:G26) | H18: =SUM(H19:H26) | I18: =SUM(I19:I26) | J18: =SUM(J19:J26)
A19: Einkäufe — Fleisch & Geflügel | B19: 0 | C19: 0 | D19: 0 | E19: 0 | F19: 0 | G19: 0 | H19: 0 | I19: 0 | J19: 0
A20: Einkäufe — Fisch & Meeresfrüchte | B20: 0 | C20: 0 | D20: 0 | E20: 0 | F20: 0 | G20: 0 | H20: 0 | I20: 0 | J20: 0
A21: Einkäufe — Obst & Gemüse | B21: 0 | C21: 0 | D21: 0 | E21: 0 | F21: 0 | G21: 0 | H21: 0 | I21: 0 | J21: 0
A22: Einkäufe — Milchprodukte & Eier | B22: 0 | C22: 0 | D22: 0 | E22: 0 | F22: 0 | G22: 0 | H22: 0 | I22: 0 | J22: 0
A23: Einkäufe — Backwaren & Konditorei | B23: 0 | C23: 0 | D23: 0 | E23: 0 | F23: 0 | G23: 0 | H23: 0 | I23: 0 | J23: 0
A24: Einkäufe — Alkoholfreie Getränke | B24: 0 | C24: 0 | D24: 0 | E24: 0 | F24: 0 | G24: 0 | H24: 0 | I24: 0 | J24: 0
A25: Einkäufe — Trocken- & Konservenware | B25: 0 | C25: 0 | D25: 0 | E25: 0 | F25: 0 | G25: 0 | H25: 0 | I25: 0 | J25: 0
A26: Einkäufe — Sonstiges | B26: 0 | C26: 0 | D26: 0 | E26: 0 | F26: 0 | G26: 0 | H26: 0 | I26: 0 | J26: 0
A28: SCHWUND (auto aus Inventar)
A29: Gesamtschwund | B29: =IFERROR(SUMIFS('📦 Inventar'!$G$30:$G$45,'📦 Inventar'!$A$30:$A$45,1),0) | C29: =IFERROR(SUMIFS('📦 Inventar'!$G$30:$G$45,'📦 Inventar'!$A$30:$A$45,2),0) | D29: =IFERROR(SUMIFS('📦 Inventar'!$G$30:$G$45,'📦 Inventar'!$A$30:$A$45,3),0) | E29: =IFERROR(SUMIFS('📦 Inventar'!$G$30:$G$45,'📦 Inventar'!$A$30:$A$45,4),0) | F29: =IFERROR(SUMIFS('📦 Inventar'!$G$30:$G$45,'📦 Inventar'!$A$30:$A$45,5),0) | G29: =IFERROR(SUMIFS('📦 Inventar'!$G$30:$G$45,'📦 Inventar'!$A$30:$A$45,6),0) | H29: =IFERROR(SUMIFS('📦 Inventar'!$G$30:$G$45,'📦 Inventar'!$A$30:$A$45,7),0) | I29: =IFERROR(SUMIFS('📦 Inventar'!$G$30:$G$45,'📦 Inventar'!$A$30:$A$45,8),0) | J29: =IFERROR(SUMIFS('📦 Inventar'!$G$30:$G$45,'📦 Inventar'!$A$30:$A$45,9),0)
A30: Schwund — Fleisch & Geflügel | B30: =IFERROR(SUMIFS('📦 Inventar'!$G$30:$G$45,'📦 Inventar'!$A$30:$A$45,1,'📦 Inventar'!$C$30:$C$45,"Fleisch & Geflügel"),0) | C30: =IFERROR(SUMIFS('📦 Inventar'!$G$30:$G$45,'📦 Inventar'!$A$30:$A$45,2,'📦 Inventar'!$C$30:$C$45,"Fleisch & Geflügel"),0) | D30: =IFERROR(SUMIFS('📦 Inventar'!$G$30:$G$45,'📦 Inventar'!$A$30:$A$45,3,'📦 Inventar'!$C$30:$C$45,"Fleisch & Geflügel"),0) | E30: =IFERROR(SUMIFS('📦 Inventar'!$G$30:$G$45,'📦 Inventar'!$A$30:$A$45,4,'📦 Inventar'!$C$30:$C$45,"Fleisch & Geflügel"),0) | F30: =IFERROR(SUMIFS('📦 Inventar'!$G$30:$G$45,'📦 Inventar'!$A$30:$A$45,5,'📦 Inventar'!$C$30:$C$45,"Fleisch & Geflügel"),0) | G30: =IFERROR(SUMIFS('📦 Inventar'!$G$30:$G$45,'📦 Inventar'!$A$30:$A$45,6,'📦 Inventar'!$C$30:$C$45,"Fleisch & Geflügel"),0) | H30: =IFERROR(SUMIFS('📦 Inventar'!$G$30:$G$45,'📦 Inventar'!$A$30:$A$45,7,'📦 Inventar'!$C$30:$C$45,"Fleisch & Geflügel"),0) | I30: =IFERROR(SUMIFS('📦 Inventar'!$G$30:$G$45,'📦 Inventar'!$A$30:$A$45,8,'📦 Inventar'!$C$30:$C$45,"Fleisch & Geflügel"),0) | J30: =IFERROR(SUMIFS('📦 Inventar'!$G$30:$G$45,'📦 Inventar'!$A$30:$A$45,9,'📦 Inventar'!$C$30:$C$45,"Fleisch & Geflügel"),0)
A31: Schwund — Fisch & Meeresfrüchte | B31: =IFERROR(SUMIFS('📦 Inventar'!$G$30:$G$45,'📦 Inventar'!$A$30:$A$45,1,'📦 Inventar'!$C$30:$C$45,"Fisch & Meeresfrüchte"),0) | C31: =IFERROR(SUMIFS('📦 Inventar'!$G$30:$G$45,'📦 Inventar'!$A$30:$A$45,2,'📦 Inventar'!$C$30:$C$45,"Fisch & Meeresfrüchte"),0) | D31: =IFERROR(SUMIFS('📦 Inventar'!$G$30:$G$45,'📦 Inventar'!$A$30:$A$45,3,'📦 Inventar'!$C$30:$C$45,"Fisch & Meeresfrüchte"),0) | E31: =IFERROR(SUMIFS('📦 Inventar'!$G$30:$G$45,'📦 Inventar'!$A$30:$A$45,4,'📦 Inventar'!$C$30:$C$45,"Fisch & Meeresfrüchte"),0) | F31: =IFERROR(SUMIFS('📦 Inventar'!$G$30:$G$45,'📦 Inventar'!$A$30:$A$45,5,'📦 Inventar'!$C$30:$C$45,"Fisch & Meeresfrüchte"),0) | G31: =IFERROR(SUMIFS('📦 Inventar'!$G$30:$G$45,'📦 Inventar'!$A$30:$A$45,6,'📦 Inventar'!$C$30:$C$45,"Fisch & Meeresfrüchte"),0) | H31: =IFERROR(SUMIFS('📦 Inventar'!$G$30:$G$45,'📦 Inventar'!$A$30:$A$45,7,'📦 Inventar'!$C$30:$C$45,"Fisch & Meeresfrüchte"),0) | I31: =IFERROR(SUMIFS('📦 Inventar'!$G$30:$G$45,'📦 Inventar'!$A$30:$A$45,8,'📦 Inventar'!$C$30:$C$45,"Fisch & Meeresfrüchte"),0) | J31: =IFERROR(SUMIFS('📦 Inventar'!$G$30:$G$45,'📦 Inventar'!$A$30:$A$45,9,'📦 Inventar'!$C$30:$C$45,"Fisch & Meeresfrüchte"),0)
A32: Schwund — Obst & Gemüse | B32: =IFERROR(SUMIFS('📦 Inventar'!$G$30:$G$45,'📦 Inventar'!$A$30:$A$45,1,'📦 Inventar'!$C$30:$C$45,"Obst & Gemüse"),0) | C32: =IFERROR(SUMIFS('📦 Inventar'!$G$30:$G$45,'📦 Inventar'!$A$30:$A$45,2,'📦 Inventar'!$C$30:$C$45,"Obst & Gemüse"),0) | D32: =IFERROR(SUMIFS('📦 Inventar'!$G$30:$G$45,'📦 Inventar'!$A$30:$A$45,3,'📦 Inventar'!$C$30:$C$45,"Obst & Gemüse"),0) | E32: =IFERROR(SUMIFS('📦 Inventar'!$G$30:$G$45,'📦 Inventar'!$A$30:$A$45,4,'📦 Inventar'!$C$30:$C$45,"Obst & Gemüse"),0) | F32: =IFERROR(SUMIFS('📦 Inventar'!$G$30:$G$45,'📦 Inventar'!$A$30:$A$45,5,'📦 Inventar'!$C$30:$C$45,"Obst & Gemüse"),0) | G32: =IFERROR(SUMIFS('📦 Inventar'!$G$30:$G$45,'📦 Inventar'!$A$30:$A$45,6,'📦 Inventar'!$C$30:$C$45,"Obst & Gemüse"),0) | H32: =IFERROR(SUMIFS('📦 Inventar'!$G$30:$G$45,'📦 Inventar'!$A$30:$A$45,7,'📦 Inventar'!$C$30:$C$45,"Obst & Gemüse"),0) | I32: =IFERROR(SUMIFS('📦 Inventar'!$G$30:$G$45,'📦 Inventar'!$A$30:$A$45,8,'📦 Inventar'!$C$30:$C$45,"Obst & Gemüse"),0) | J32: =IFERROR(SUMIFS('📦 Inventar'!$G$30:$G$45,'📦 Inventar'!$A$30:$A$45,9,'📦 Inventar'!$C$30:$C$45,"Obst & Gemüse"),0)
A33: Schwund — Milchprodukte & Eier | B33: =IFERROR(SUMIFS('📦 Inventar'!$G$30:$G$45,'📦 Inventar'!$A$30:$A$45,1,'📦 Inventar'!$C$30:$C$45,"Milchprodukte & Eier"),0) | C33: =IFERROR(SUMIFS('📦 Inventar'!$G$30:$G$45,'📦 Inventar'!$A$30:$A$45,2,'📦 Inventar'!$C$30:$C$45,"Milchprodukte & Eier"),0) | D33: =IFERROR(SUMIFS('📦 Inventar'!$G$30:$G$45,'📦 Inventar'!$A$30:$A$45,3,'📦 Inventar'!$C$30:$C$45,"Milchprodukte & Eier"),0) | E33: =IFERROR(SUMIFS('📦 Inventar'!$G$30:$G$45,'📦 Inventar'!$A$30:$A$45,4,'📦 Inventar'!$C$30:$C$45,"Milchprodukte & Eier"),0) | F33: =IFERROR(SUMIFS('📦 Inventar'!$G$30:$G$45,'📦 Inventar'!$A$30:$A$45,5,'📦 Inventar'!$C$30:$C$45,"Milchprodukte & Eier"),0) | G33: =IFERROR(SUMIFS('📦 Inventar'!$G$30:$G$45,'📦 Inventar'!$A$30:$A$45,6,'📦 Inventar'!$C$30:$C$45,"Milchprodukte & Eier"),0) | H33: =IFERROR(SUMIFS('📦 Inventar'!$G$30:$G$45,'📦 Inventar'!$A$30:$A$45,7,'📦 Inventar'!$C$30:$C$45,"Milchprodukte & Eier"),0) | I33: =IFERROR(SUMIFS('📦 Inventar'!$G$30:$G$45,'📦 Inventar'!$A$30:$A$45,8,'📦 Inventar'!$C$30:$C$45,"Milchprodukte & Eier"),0) | J33: =IFERROR(SUMIFS('📦 Inventar'!$G$30:$G$45,'📦 Inventar'!$A$30:$A$45,9,'📦 Inventar'!$C$30:$C$45,"Milchprodukte & Eier"),0)
A34: Schwund — Backwaren & Konditorei | B34: =IFERROR(SUMIFS('📦 Inventar'!$G$30:$G$45,'📦 Inventar'!$A$30:$A$45,1,'📦 Inventar'!$C$30:$C$45,"Backwaren & Konditorei"),0) | C34: =IFERROR(SUMIFS('📦 Inventar'!$G$30:$G$45,'📦 Inventar'!$A$30:$A$45,2,'📦 Inventar'!$C$30:$C$45,"Backwaren & Konditorei"),0) | D34: =IFERROR(SUMIFS('📦 Inventar'!$G$30:$G$45,'📦 Inventar'!$A$30:$A$45,3,'📦 Inventar'!$C$30:$C$45,"Backwaren & Konditorei"),0) | E34: =IFERROR(SUMIFS('📦 Inventar'!$G$30:$G$45,'📦 Inventar'!$A$30:$A$45,4,'📦 Inventar'!$C$30:$C$45,"Backwaren & Konditorei"),0) | F34: =IFERROR(SUMIFS('📦 Inventar'!$G$30:$G$45,'📦 Inventar'!$A$30:$A$45,5,'📦 Inventar'!$C$30:$C$45,"Backwaren & Konditorei"),0) | G34: =IFERROR(SUMIFS('📦 Inventar'!$G$30:$G$45,'📦 Inventar'!$A$30:$A$45,6,'📦 Inventar'!$C$30:$C$45,"Backwaren & Konditorei"),0) | H34: =IFERROR(SUMIFS('📦 Inventar'!$G$30:$G$45,'📦 Inventar'!$A$30:$A$45,7,'📦 Inventar'!$C$30:$C$45,"Backwaren & Konditorei"),0) | I34: =IFERROR(SUMIFS('📦 Inventar'!$G$30:$G$45,'📦 Inventar'!$A$30:$A$45,8,'📦 Inventar'!$C$30:$C$45,"Backwaren & Konditorei"),0) | J34: =IFERROR(SUMIFS('📦 Inventar'!$G$30:$G$45,'📦 Inventar'!$A$30:$A$45,9,'📦 Inventar'!$C$30:$C$45,"Backwaren & Konditorei"),0)
A35: Schwund — Alkoholfreie Getränke | B35: =IFERROR(SUMIFS('📦 Inventar'!$G$30:$G$45,'📦 Inventar'!$A$30:$A$45,1,'📦 Inventar'!$C$30:$C$45,"Alkoholfreie Getränke"),0) | C35: =IFERROR(SUMIFS('📦 Inventar'!$G$30:$G$45,'📦 Inventar'!$A$30:$A$45,2,'📦 Inventar'!$C$30:$C$45,"Alkoholfreie Getränke"),0) | D35: =IFERROR(SUMIFS('📦 Inventar'!$G$30:$G$45,'📦 Inventar'!$A$30:$A$45,3,'📦 Inventar'!$C$30:$C$45,"Alkoholfreie Getränke"),0) | E35: =IFERROR(SUMIFS('📦 Inventar'!$G$30:$G$45,'📦 Inventar'!$A$30:$A$45,4,'📦 Inventar'!$C$30:$C$45,"Alkoholfreie Getränke"),0) | F35: =IFERROR(SUMIFS('📦 Inventar'!$G$30:$G$45,'📦 Inventar'!$A$30:$A$45,5,'📦 Inventar'!$C$30:$C$45,"Alkoholfreie Getränke"),0) | G35: =IFERROR(SUMIFS('📦 Inventar'!$G$30:$G$45,'📦 Inventar'!$A$30:$A$45,6,'📦 Inventar'!$C$30:$C$45,"Alkoholfreie Getränke"),0) | H35: =IFERROR(SUMIFS('📦 Inventar'!$G$30:$G$45,'📦 Inventar'!$A$30:$A$45,7,'📦 Inventar'!$C$30:$C$45,"Alkoholfreie Getränke"),0) | I35: =IFERROR(SUMIFS('📦 Inventar'!$G$30:$G$45,'📦 Inventar'!$A$30:$A$45,8,'📦 Inventar'!$C$30:$C$45,"Alkoholfreie Getränke"),0) | J35: =IFERROR(SUMIFS('📦 Inventar'!$G$30:$G$45,'📦 Inventar'!$A$30:$A$45,9,'📦 Inventar'!$C$30:$C$45,"Alkoholfreie Getränke"),0)
A36: Schwund — Trocken- & Konservenware | B36: =IFERROR(SUMIFS('📦 Inventar'!$G$30:$G$45,'📦 Inventar'!$A$30:$A$45,1,'📦 Inventar'!$C$30:$C$45,"Trocken- & Konservenware"),0) | C36: =IFERROR(SUMIFS('📦 Inventar'!$G$30:$G$45,'📦 Inventar'!$A$30:$A$45,2,'📦 Inventar'!$C$30:$C$45,"Trocken- & Konservenware"),0) | D36: =IFERROR(SUMIFS('📦 Inventar'!$G$30:$G$45,'📦 Inventar'!$A$30:$A$45,3,'📦 Inventar'!$C$30:$C$45,"Trocken- & Konservenware"),0) | E36: =IFERROR(SUMIFS('📦 Inventar'!$G$30:$G$45,'📦 Inventar'!$A$30:$A$45,4,'📦 Inventar'!$C$30:$C$45,"Trocken- & Konservenware"),0) | F36: =IFERROR(SUMIFS('📦 Inventar'!$G$30:$G$45,'📦 Inventar'!$A$30:$A$45,5,'📦 Inventar'!$C$30:$C$45,"Trocken- & Konservenware"),0) | G36: =IFERROR(SUMIFS('📦 Inventar'!$G$30:$G$45,'📦 Inventar'!$A$30:$A$45,6,'📦 Inventar'!$C$30:$C$45,"Trocken- & Konservenware"),0) | H36: =IFERROR(SUMIFS('📦 Inventar'!$G$30:$G$45,'📦 Inventar'!$A$30:$A$45,7,'📦 Inventar'!$C$30:$C$45,"Trocken- & Konservenware"),0) | I36: =IFERROR(SUMIFS('📦 Inventar'!$G$30:$G$45,'📦 Inventar'!$A$30:$A$45,8,'📦 Inventar'!$C$30:$C$45,"Trocken- & Konservenware"),0) | J36: =IFERROR(SUMIFS('📦 Inventar'!$G$30:$G$45,'📦 Inventar'!$A$30:$A$45,9,'📦 Inventar'!$C$30:$C$45,"Trocken- & Konservenware"),0)
A37: Schwund — Sonstiges | B37: =IFERROR(SUMIFS('📦 Inventar'!$G$30:$G$45,'📦 Inventar'!$A$30:$A$45,1,'📦 Inventar'!$C$30:$C$45,"Sonstiges"),0) | C37: =IFERROR(SUMIFS('📦 Inventar'!$G$30:$G$45,'📦 Inventar'!$A$30:$A$45,2,'📦 Inventar'!$C$30:$C$45,"Sonstiges"),0) | D37: =IFERROR(SUMIFS('📦 Inventar'!$G$30:$G$45,'📦 Inventar'!$A$30:$A$45,3,'📦 Inventar'!$C$30:$C$45,"Sonstiges"),0) | E37: =IFERROR(SUMIFS('📦 Inventar'!$G$30:$G$45,'📦 Inventar'!$A$30:$A$45,4,'📦 Inventar'!$C$30:$C$45,"Sonstiges"),0) | F37: =IFERROR(SUMIFS('📦 Inventar'!$G$30:$G$45,'📦 Inventar'!$A$30:$A$45,5,'📦 Inventar'!$C$30:$C$45,"Sonstiges"),0) | G37: =IFERROR(SUMIFS('📦 Inventar'!$G$30:$G$45,'📦 Inventar'!$A$30:$A$45,6,'📦 Inventar'!$C$30:$C$45,"Sonstiges"),0) | H37: =IFERROR(SUMIFS('📦 Inventar'!$G$30:$G$45,'📦 Inventar'!$A$30:$A$45,7,'📦 Inventar'!$C$30:$C$45,"Sonstiges"),0) | I37: =IFERROR(SUMIFS('📦 Inventar'!$G$30:$G$45,'📦 Inventar'!$A$30:$A$45,8,'📦 Inventar'!$C$30:$C$45,"Sonstiges"),0) | J37: =IFERROR(SUMIFS('📦 Inventar'!$G$30:$G$45,'📦 Inventar'!$A$30:$A$45,9,'📦 Inventar'!$C$30:$C$45,"Sonstiges"),0)
A39: GESAMTKOSTEN (Einkäufe + Schwund)
A40: Gesamte Lebensmittelkosten | B40: =B18+B29 | C40: =C18+C29 | D40: =D18+D29 | E40: =E18+E29 | F40: =F18+F29 | G40: =G18+G29 | H40: =H18+H29 | I40: =I18+I29 | J40: =J18+J29
A42: KENNZAHLEN
A43: Food-Cost % Global | B43: =IFERROR(B40/B7,0) | C43: =IFERROR(C40/C7,0) | D43: =IFERROR(D40/D7,0) | E43: =IFERROR(E40/E7,0) | F43: =IFERROR(F40/F7,0) | G43: =IFERROR(G40/G7,0) | H43: =IFERROR(H40/H7,0) | I43: =IFERROR(I40/I7,0) | J43: =IFERROR(J40/J7,0)
A44: FC% Fleisch & Geflügel | B44: =IFERROR((B19+B30)/B8,0) | C44: =IFERROR((C19+C30)/C8,0) | D44: =IFERROR((D19+D30)/D8,0) | E44: =IFERROR((E19+E30)/E8,0) | F44: =IFERROR((F19+F30)/F8,0) | G44: =IFERROR((G19+G30)/G8,0) | H44: =IFERROR((H19+H30)/H8,0) | I44: =IFERROR((I19+I30)/I8,0) | J44: =IFERROR((J19+J30)/J8,0)
A45: FC% Fisch & Meeresfrüchte | B45: =IFERROR((B20+B31)/B9,0) | C45: =IFERROR((C20+C31)/C9,0) | D45: =IFERROR((D20+D31)/D9,0) | E45: =IFERROR((E20+E31)/E9,0) | F45: =IFERROR((F20+F31)/F9,0) | G45: =IFERROR((G20+G31)/G9,0) | H45: =IFERROR((H20+H31)/H9,0) | I45: =IFERROR((I20+I31)/I9,0) | J45: =IFERROR((J20+J31)/J9,0)
...

Sheet 📦 Inventar
A1: INVENTAR- UND SCHWUND-KONTROLLE
A2: ="Währung: "&'⚙️ Einstellungen'!$B$10&" | Maßsystem: "&'⚙️ Einstellungen'!$B$11
A4: Stückkosten werden automatisch aus Lieferanten per SVERWEIS geholt. Schwund beeinflusst die wöchentlichen Food-Cost.
A5: Artikel | B5: Kategorie | C5: Einheit | D5: Anfangsbestand | E5: Einkäufe | F5: Endbestand | G5: Verbrauch | H5: ="Stückkosten ("&'⚙️ Einstellungen'!$B$10&")" | I5: ="Gesamtkosten ("&'⚙️ Einstellungen'!$B$10&")"
A6: Entrecôte | B6: Fleisch & Geflügel | C6: kg | D6: 5 | E6: 20 | F6: 3.5 | G6: =IFERROR(IF(D6="","",D6+E6-F6),"") | H6: =IFERROR(VLOOKUP(A6,'🏪 Lieferanten'!$A$6:$E$20,5,FALSE),0) | I6: =IFERROR(IF(G6="","",G6*H6),"")
A7: Ganzes Hähnchen | B7: Fleisch & Geflügel | C7: kg | D7: 8 | E7: 15 | F7: 4 | G7: =IFERROR(IF(D7="","",D7+E7-F7),"") | H7: =IFERROR(VLOOKUP(A7,'🏪 Lieferanten'!$A$6:$E$20,5,FALSE),0) | I7: =IFERROR(IF(G7="","",G7*H7),"")
A8: Frischer Lachs | B8: Fisch & Meeresfrüchte | C8: kg | D8: 3 | E8: 8 | F8: 1.5 | G8: =IFERROR(IF(D8="","",D8+E8-F8),"") | H8: =IFERROR(VLOOKUP(A8,'🏪 Lieferanten'!$A$6:$E$20,5,FALSE),0) | I8: =IFERROR(IF(G8="","",G8*H8),"")
A9: Kirschtomaten | B9: Obst & Gemüse | C9: kg | D9: 10 | E9: 25 | F9: 6 | G9: =IFERROR(IF(D9="","",D9+E9-F9),"") | H9: =IFERROR(VLOOKUP(A9,'🏪 Lieferanten'!$A$6:$E$20,5,FALSE),0) | I9: =IFERROR(IF(G9="","",G9*H9),"")
A10: Kartoffeln | B10: Obst & Gemüse | C10: kg | D10: 20 | E10: 40 | F10: 12 | G10: =IFERROR(IF(D10="","",D10+E10-F10),"") | H10: =IFERROR(VLOOKUP(A10,'🏪 Lieferanten'!$A$6:$E$20,5,FALSE),0) | I10: =IFERROR(IF(G10="","",G10*H10),"")
A11: Manchego-Käse | B11: Milchprodukte & Eier | C11: kg | D11: 2 | E11: 5 | F11: 1 | G11: =IFERROR(IF(D11="","",D11+E11-F11),"") | H11: =IFERROR(VLOOKUP(A11,'🏪 Lieferanten'!$A$6:$E$20,5,FALSE),0) | I11: =IFERROR(IF(G11="","",G11*H11),"")
A12: Freilandeier L | B12: Milchprodukte & Eier | C12: Dutzend | D12: 4 | E12: 12 | F12: 2 | G12: =IFERROR(IF(D12="","",D12+E12-F12),"") | H12: =IFERROR(VLOOKUP(A12,'🏪 Lieferanten'!$A$6:$E$20,5,FALSE),0) | I12: =IFERROR(IF(G12="","",G12*H12),"")
A13: Weizenmehl Type 550 | B13: Backwaren & Konditorei | C13: kg | D13: 10 | E13: 20 | F13: 5 | G13: =IFERROR(IF(D13="","",D13+E13-F13),"") | H13: =IFERROR(VLOOKUP(A13,'🏪 Lieferanten'!$A$6:$E$20,5,FALSE),0) | I13: =IFERROR(IF(G13="","",G13*H13),"")
A14: Mineralwasser 1.5L | B14: Alkoholfreie Getränke | C14: Kiste 12St | D14: 4 | E14: 16 | F14: 3 | G14: =IFERROR(IF(D14="","",D14+E14-F14),"") | H14: =IFERROR(VLOOKUP(A14,'🏪 Lieferanten'!$A$6:$E$20,5,FALSE),0) | I14: =IFERROR(IF(G14="","",G14*H14),"")
A15: Natives Olivenöl extra | B15: Trocken- & Konservenware | C15: Liter | D15: 5 | E15: 10 | F15: 3 | G15: =IFERROR(IF(D15="","",D15+E15-F15),"") | H15: =IFERROR(VLOOKUP(A15,'🏪 Lieferanten'!$A$6:$E$20,5,FALSE),0) | I15: =IFERROR(IF(G15="","",G15*H15),"")
G16: =IFERROR(IF(D16="","",D16+E16-F16),"") | H16: =IFERROR(VLOOKUP(A16,'🏪 Lieferanten'!$A$6:$E$20,5,FALSE),0) | I16: =IFERROR(IF(G16="","",G16*H16),"")
G17: =IFERROR(IF(D17="","",D17+E17-F17),"") | H17: =IFERROR(VLOOKUP(A17,'🏪 Lieferanten'!$A$6:$E$20,5,FALSE),0) | I17: =IFERROR(IF(G17="","",G17*H17),"")
G18: =IFERROR(IF(D18="","",D18+E18-F18),"") | H18: =IFERROR(VLOOKUP(A18,'🏪 Lieferanten'!$A$6:$E$20,5,FALSE),0) | I18: =IFERROR(IF(G18="","",G18*H18),"")
G19: =IFERROR(IF(D19="","",D19+E19-F19),"") | H19: =IFERROR(VLOOKUP(A19,'🏪 Lieferanten'!$A$6:$E$20,5,FALSE),0) | I19: =IFERROR(IF(G19="","",G19*H19),"")
G20: =IFERROR(IF(D20="","",D20+E20-F20),"") | H20: =IFERROR(VLOOKUP(A20,'🏪 Lieferanten'!$A$6:$E$20,5,FALSE),0) | I20: =IFERROR(IF(G20="","",G20*H20),"")
G21: =IFERROR(IF(D21="","",D21+E21-F21),"") | H21: =IFERROR(VLOOKUP(A21,'🏪 Lieferanten'!$A$6:$E$20,5,FALSE),0) | I21: =IFERROR(IF(G21="","",G21*H21),"")
G22: =IFERROR(IF(D22="","",D22+E22-F22),"") | H22: =IFERROR(VLOOKUP(A22,'🏪 Lieferanten'!$A$6:$E$20,5,FALSE),0) | I22: =IFERROR(IF(G22="","",G22*H22),"")
G23: =IFERROR(IF(D23="","",D23+E23-F23),"") | H23: =IFERROR(VLOOKUP(A23,'🏪 Lieferanten'!$A$6:$E$20,5,FALSE),0) | I23: =IFERROR(IF(G23="","",G23*H23),"")
G24: =IFERROR(IF(D24="","",D24+E24-F24),"") | H24: =IFERROR(VLOOKUP(A24,'🏪 Lieferanten'!$A$6:$E$20,5,FALSE),0) | I24: =IFERROR(IF(G24="","",G24*H24),"")
G25: =IFERROR(IF(D25="","",D25+E25-F25),"") | H25: =IFERROR(VLOOKUP(A25,'🏪 Lieferanten'!$A$6:$E$20,5,FALSE),0) | I25: =IFERROR(IF(G25="","",G25*H25),"")
A26: GESAMTKOSTEN INVENTAR | I26: =IFERROR(SUMIF(I6:I25,">0"),0)
A28: SCHWUND-PROTOKOLL — BEEINFLUSST WÖCHENTLICHE FOOD-COST
A29: Woche | B29: Artikel | C29: Kategorie | D29: Menge | E29: Einheit | F29: ="Stückkosten ("&'⚙️ Einstellungen'!$B$10&")" | G29: ="Schwundkosten ("&'⚙️ Einstellungen'!$B$10&")" | H29: Ursache | I29: Datum | J29: Schicht | K29: Mitarbeiter
A30: 4 | B30: Frischer Lachs | C30: Fisch & Meeresfrüchte | D30: 2 | E30: kg | F30: =IFERROR(VLOOKUP(B30,'🏪 Lieferanten'!$A$6:$E$20,5,FALSE),0) | G30: =IFERROR(IF(D30="","",D30*F30),0) | H30: Kühler defekt | I30: 15.04.2025 | J30: Abend | K30: Küchenchef
A31: 2 | B31: Kirschtomaten | C31: Obst & Gemüse | D31: 3 | E31: kg | F31: =IFERROR(VLOOKUP(B31,'🏪 Lieferanten'!$A$6:$E$20,5,FALSE),0) | G31: =IFERROR(IF(D31="","",D31*F31),0) | H31: Überreif geliefert | I31: 05.04.2025 | J31: Mittag | K31: Sous-Chef
A32: 6 | B32: Ganzes Hähnchen | C32: Fleisch & Geflügel | D32: 1.5 | E32: kg | F32: =IFERROR(VLOOKUP(B32,'🏪 Lieferanten'!$A$6:$E$20,5,FALSE),0) | G32: =IFERROR(IF(D32="","",D32*F32),0) | H32: Abgelaufen | I32: 20.04.2025 | J32: Vormittag | K32: Küchenchef
F33: =IFERROR(VLOOKUP(B33,'🏪 Lieferanten'!$A$6:$E$20,5,FALSE),0) | G33: =IFERROR(IF(D33="","",D33*F33),0)
F34: =IFERROR(VLOOKUP(B34,'🏪 Lieferanten'!$A$6:$E$20,5,FALSE),0) | G34: =IFERROR(IF(D34="","",D34*F34),0)
F35: =IFERROR(VLOOKUP(B35,'🏪 Lieferanten'!$A$6:$E$20,5,FALSE),0) | G35: =IFERROR(IF(D35="","",D35*F35),0)
F36: =IFERROR(VLOOKUP(B36,'🏪 Lieferanten'!$A$6:$E$20,5,FALSE),0) | G36: =IFERROR(IF(D36="","",D36*F36),0)
F37: =IFERROR(VLOOKUP(B37,'🏪 Lieferanten'!$A$6:$E$20,5,FALSE),0) | G37: =IFERROR(IF(D37="","",D37*F37),0)
F38: =IFERROR(VLOOKUP(B38,'🏪 Lieferanten'!$A$6:$E$20,5,FALSE),0) | G38: =IFERROR(IF(D38="","",D38*F38),0)
F39: =IFERROR(VLOOKUP(B39,'🏪 Lieferanten'!$A$6:$E$20,5,FALSE),0) | G39: =IFERROR(IF(D39="","",D39*F39),0)
F40: =IFERROR(VLOOKUP(B40,'🏪 Lieferanten'!$A$6:$E$20,5,FALSE),0) | G40: =IFERROR(IF(D40="","",D40*F40),0)
F41: =IFERROR(VLOOKUP(B41,'🏪 Lieferanten'!$A$6:$E$20,5,FALSE),0) | G41: =IFERROR(IF(D41="","",D41*F41),0)
F42: =IFERROR(VLOOKUP(B42,'🏪 Lieferanten'!$A$6:$E$20,5,FALSE),0) | G42: =IFERROR(IF(D42="","",D42*F42),0)
...

Sheet 🏪 Lieferanten
A1: LIEFERANTEN & PREISLISTE
A2: ="Währung: "&'⚙️ Einstellungen'!$B$10&" | Maßsystem: "&'⚙️ Einstellungen'!$B$11
A4: ⚠ Einzige Preisquelle. Hier aktualisieren — Kosten in Inventar und Schwund-Log berechnen sich automatisch neu.
A5: Artikel | B5: Kategorie | C5: Lieferant | D5: Einheit | E5: ="Aktueller Preis ("&'⚙️ Einstellungen'!$B$10&")" | F5: ="Vorheriger Preis ("&'⚙️ Einstellungen'!$B$10&")" | G5: ="Änderung ("&'⚙️ Einstellungen'!$B$10&")" | H5: Änderung % | I5: Zuletzt aktualisiert | J5: Notizen
A6: Entrecôte | B6: Fleisch & Geflügel | C6: Metzgerei García | D6: kg | E6: 18.5 | F6: 17.8 | G6: =IFERROR(IF(E6="","",E6-F6),"") | H6: =IFERROR(IF(OR(F6="",F6=0),"",(E6-F6)/F6),"")
A7: Ganzes Hähnchen | B7: Fleisch & Geflügel | C7: Pérez Großhandel | D7: kg | E7: 4.2 | F7: 4 | G7: =IFERROR(IF(E7="","",E7-F7),"") | H7: =IFERROR(IF(OR(F7="",F7=0),"",(E7-F7)/F7),"")
A8: Frischer Lachs | B8: Fisch & Meeresfrüchte | C8: Fischgroßhandel Nord | D8: kg | E8: 14.8 | F8: 15.2 | G8: =IFERROR(IF(E8="","",E8-F8),"") | H8: =IFERROR(IF(OR(F8="",F8=0),"",(E8-F8)/F8),"")
A9: Kirschtomaten | B9: Obst & Gemüse | C9: Großmarkt | D9: kg | E9: 1.8 | F9: 1.6 | G9: =IFERROR(IF(E9="","",E9-F9),"") | H9: =IFERROR(IF(OR(F9="",F9=0),"",(E9-F9)/F9),"")
A10: Kartoffeln | B10: Obst & Gemüse | C10: Großmarkt | D10: kg | E10: 0.65 | F10: 0.65 | G10: =IFERROR(IF(E10="","",E10-F10),"") | H10: =IFERROR(IF(OR(F10="",F10=0),"",(E10-F10)/F10),"")
A11: Manchego-Käse | B11: Milchprodukte & Eier | C11: Käserei Handwerk | D11: kg | E11: 12 | F11: 11.5 | G11: =IFERROR(IF(E11="","",E11-F11),"") | H11: =IFERROR(IF(OR(F11="",F11=0),"",(E11-F11)/F11),"")
A12: Freilandeier L | B12: Milchprodukte & Eier | C12: Bauernhof Einigkeit | D12: Dutzend | E12: 2.4 | F12: 2.2 | G12: =IFERROR(IF(E12="","",E12-F12),"") | H12: =IFERROR(IF(OR(F12="",F12=0),"",(E12-F12)/F12),"")
A13: Weizenmehl Type 550 | B13: Backwaren & Konditorei | C13: Roca Mühle | D13: kg | E13: 0.9 | F13: 0.85 | G13: =IFERROR(IF(E13="","",E13-F13),"") | H13: =IFERROR(IF(OR(F13="",F13=0),"",(E13-F13)/F13),"")
A14: Natives Olivenöl extra | B14: Trocken- & Konservenware | C14: Ölhandel Martínez | D14: Liter | E14: 6.5 | F14: 6 | G14: =IFERROR(IF(E14="","",E14-F14),"") | H14: =IFERROR(IF(OR(F14="",F14=0),"",(E14-F14)/F14),"")
A15: Mineralwasser 1.5L | B15: Alkoholfreie Getränke | C15: Nord Vertrieb | D15: Kiste 12St | E15: 4.2 | F15: 4.2 | G15: =IFERROR(IF(E15="","",E15-F15),"") | H15: =IFERROR(IF(OR(F15="",F15=0),"",(E15-F15)/F15),"")
G16: =IFERROR(IF(E16="","",E16-F16),"") | H16: =IFERROR(IF(OR(F16="",F16=0),"",(E16-F16)/F16),"")
G17: =IFERROR(IF(E17="","",E17-F17),"") | H17: =IFERROR(IF(OR(F17="",F17=0),"",(E17-F17)/F17),"")
G18: =IFERROR(IF(E18="","",E18-F18),"") | H18: =IFERROR(IF(OR(F18="",F18=0),"",(E18-F18)/F18),"")
G19: =IFERROR(IF(E19="","",E19-F19),"") | H19: =IFERROR(IF(OR(F19="",F19=0),"",(E19-F19)/F19),"")
G20: =IFERROR(IF(E20="","",E20-F20),"") | H20: =IFERROR(IF(OR(F20="",F20=0),"",(E20-F20)/F20),"")
A22: LeSousChef · lesouschef.com · Dozo Tech · SYSTEMS THAT BREATHE
